2021-02-03 00:31:58,075 INFO: microBlog startup [in /Volumes/Space/Programming/microBlogFlask/myapp/__init__.py:47]
2021-02-03 00:32:14,492 ERROR: Exception on /edit_profile [POST] [in /Users/shihab/opt/anaconda3/lib/python3.8/site-packages/flask/app.py:1891]
Traceback (most recent call last):
  File "/Users/shihab/opt/anaconda3/lib/python3.8/site-packages/sqlalchemy/engine/base.py", line 1277, in _execute_context
    self.dialect.do_execute(
  File "/Users/shihab/opt/anaconda3/lib/python3.8/site-packages/sqlalchemy/engine/default.py", line 593, in do_execute
    cursor.execute(statement, parameters)
sqlite3.IntegrityError: UNIQUE constraint failed: user.username

The above exception was the direct cause of the following exception:

Traceback (most recent call last):
  File "/Users/shihab/opt/anaconda3/lib/python3.8/site-packages/flask/app.py", line 2447, in wsgi_app
    response = self.full_dispatch_request()
  File "/Users/shihab/opt/anaconda3/lib/python3.8/site-packages/flask/app.py", line 1952, in full_dispatch_request
    rv = self.handle_user_exception(e)
  File "/Users/shihab/opt/anaconda3/lib/python3.8/site-packages/flask/app.py", line 1821, in handle_user_exception
    reraise(exc_type, exc_value, tb)
  File "/Users/shihab/opt/anaconda3/lib/python3.8/site-packages/flask/_compat.py", line 39, in reraise
    raise value
  File "/Users/shihab/opt/anaconda3/lib/python3.8/site-packages/flask/app.py", line 1950, in full_dispatch_request
    rv = self.dispatch_request()
  File "/Users/shihab/opt/anaconda3/lib/python3.8/site-packages/flask/app.py", line 1936, in dispatch_request
    return self.view_functions[rule.endpoint](**req.view_args)
  File "/Users/shihab/opt/anaconda3/lib/python3.8/site-packages/flask_login/utils.py", line 272, in decorated_view
    return func(*args, **kwargs)
  File "/Volumes/Space/Programming/microBlogFlask/myapp/routes.py", line 101, in edit_profile
    db.session.commit()
  File "/Users/shihab/opt/anaconda3/lib/python3.8/site-packages/sqlalchemy/orm/scoping.py", line 163, in do
    return getattr(self.registry(), name)(*args, **kwargs)
  File "/Users/shihab/opt/anaconda3/lib/python3.8/site-packages/sqlalchemy/orm/session.py", line 1042, in commit
    self.transaction.commit()
  File "/Users/shihab/opt/anaconda3/lib/python3.8/site-packages/sqlalchemy/orm/session.py", line 504, in commit
    self._prepare_impl()
  File "/Users/shihab/opt/anaconda3/lib/python3.8/site-packages/sqlalchemy/orm/session.py", line 483, in _prepare_impl
    self.session.flush()
  File "/Users/shihab/opt/anaconda3/lib/python3.8/site-packages/sqlalchemy/orm/session.py", line 2523, in flush
    self._flush(objects)
  File "/Users/shihab/opt/anaconda3/lib/python3.8/site-packages/sqlalchemy/orm/session.py", line 2664, in _flush
    transaction.rollback(_capture_exception=True)
  File "/Users/shihab/opt/anaconda3/lib/python3.8/site-packages/sqlalchemy/util/langhelpers.py", line 68, in __exit__
    compat.raise_(
  File "/Users/shihab/opt/anaconda3/lib/python3.8/site-packages/sqlalchemy/util/compat.py", line 178, in raise_
    raise exception
  File "/Users/shihab/opt/anaconda3/lib/python3.8/site-packages/sqlalchemy/orm/session.py", line 2624, in _flush
    flush_context.execute()
  File "/Users/shihab/opt/anaconda3/lib/python3.8/site-packages/sqlalchemy/orm/unitofwork.py", line 422, in execute
    rec.execute(self)
  File "/Users/shihab/opt/anaconda3/lib/python3.8/site-packages/sqlalchemy/orm/unitofwork.py", line 586, in execute
    persistence.save_obj(
  File "/Users/shihab/opt/anaconda3/lib/python3.8/site-packages/sqlalchemy/orm/persistence.py", line 230, in save_obj
    _emit_update_statements(
  File "/Users/shihab/opt/anaconda3/lib/python3.8/site-packages/sqlalchemy/orm/persistence.py", line 994, in _emit_update_statements
    c = cached_connections[connection].execute(
  File "/Users/shihab/opt/anaconda3/lib/python3.8/site-packages/sqlalchemy/engine/base.py", line 1014, in execute
    return meth(self, multiparams, params)
  File "/Users/shihab/opt/anaconda3/lib/python3.8/site-packages/sqlalchemy/sql/elements.py", line 298, in _execute_on_connection
    return connection._execute_clauseelement(self, multiparams, params)
  File "/Users/shihab/opt/anaconda3/lib/python3.8/site-packages/sqlalchemy/engine/base.py", line 1127, in _execute_clauseelement
    ret = self._execute_context(
  File "/Users/shihab/opt/anaconda3/lib/python3.8/site-packages/sqlalchemy/engine/base.py", line 1317, in _execute_context
    self._handle_dbapi_exception(
  File "/Users/shihab/opt/anaconda3/lib/python3.8/site-packages/sqlalchemy/engine/base.py", line 1511, in _handle_dbapi_exception
    util.raise_(
  File "/Users/shihab/opt/anaconda3/lib/python3.8/site-packages/sqlalchemy/util/compat.py", line 178, in raise_
    raise exception
  File "/Users/shihab/opt/anaconda3/lib/python3.8/site-packages/sqlalchemy/engine/base.py", line 1277, in _execute_context
    self.dialect.do_execute(
  File "/Users/shihab/opt/anaconda3/lib/python3.8/site-packages/sqlalchemy/engine/default.py", line 593, in do_execute
    cursor.execute(statement, parameters)
sqlalchemy.exc.IntegrityError: (sqlite3.IntegrityError) UNIQUE constraint failed: user.username
[SQL: UPDATE user SET username=?, about_me=? WHERE user.id = ?]
[parameters: ('ohn', 'hello there :)', 2)]
(Background on this error at: http://sqlalche.me/e/13/gkpj)
2021-02-03 23:05:43,874 INFO: microBlog startup [in /Volumes/Space/Programming/microBlogFlask/myapp/__init__.py:47]
2021-02-03 23:06:08,834 ERROR: Exception on /edit_profile [GET] [in /Users/shihab/opt/anaconda3/lib/python3.8/site-packages/flask/app.py:1891]
Traceback (most recent call last):
  File "/Users/shihab/opt/anaconda3/lib/python3.8/site-packages/flask/app.py", line 2447, in wsgi_app
    response = self.full_dispatch_request()
  File "/Users/shihab/opt/anaconda3/lib/python3.8/site-packages/flask/app.py", line 1952, in full_dispatch_request
    rv = self.handle_user_exception(e)
  File "/Users/shihab/opt/anaconda3/lib/python3.8/site-packages/flask/app.py", line 1821, in handle_user_exception
    reraise(exc_type, exc_value, tb)
  File "/Users/shihab/opt/anaconda3/lib/python3.8/site-packages/flask/_compat.py", line 39, in reraise
    raise value
  File "/Users/shihab/opt/anaconda3/lib/python3.8/site-packages/flask/app.py", line 1950, in full_dispatch_request
    rv = self.dispatch_request()
  File "/Users/shihab/opt/anaconda3/lib/python3.8/site-packages/flask/app.py", line 1936, in dispatch_request
    return self.view_functions[rule.endpoint](**req.view_args)
  File "/Users/shihab/opt/anaconda3/lib/python3.8/site-packages/flask_login/utils.py", line 272, in decorated_view
    return func(*args, **kwargs)
  File "/Volumes/Space/Programming/microBlogFlask/myapp/routes.py", line 97, in edit_profile
    form = EditProfileForm()
  File "/Users/shihab/opt/anaconda3/lib/python3.8/site-packages/wtforms/form.py", line 208, in __call__
    return type.__call__(cls, *args, **kwargs)
TypeError: __init__() missing 1 required positional argument: 'original_username'
2021-02-03 23:06:14,801 ERROR: Exception on /edit_profile [GET] [in /Users/shihab/opt/anaconda3/lib/python3.8/site-packages/flask/app.py:1891]
Traceback (most recent call last):
  File "/Users/shihab/opt/anaconda3/lib/python3.8/site-packages/flask/app.py", line 2447, in wsgi_app
    response = self.full_dispatch_request()
  File "/Users/shihab/opt/anaconda3/lib/python3.8/site-packages/flask/app.py", line 1952, in full_dispatch_request
    rv = self.handle_user_exception(e)
  File "/Users/shihab/opt/anaconda3/lib/python3.8/site-packages/flask/app.py", line 1821, in handle_user_exception
    reraise(exc_type, exc_value, tb)
  File "/Users/shihab/opt/anaconda3/lib/python3.8/site-packages/flask/_compat.py", line 39, in reraise
    raise value
  File "/Users/shihab/opt/anaconda3/lib/python3.8/site-packages/flask/app.py", line 1950, in full_dispatch_request
    rv = self.dispatch_request()
  File "/Users/shihab/opt/anaconda3/lib/python3.8/site-packages/flask/app.py", line 1936, in dispatch_request
    return self.view_functions[rule.endpoint](**req.view_args)
  File "/Users/shihab/opt/anaconda3/lib/python3.8/site-packages/flask_login/utils.py", line 272, in decorated_view
    return func(*args, **kwargs)
  File "/Volumes/Space/Programming/microBlogFlask/myapp/routes.py", line 97, in edit_profile
    form = EditProfileForm()
  File "/Users/shihab/opt/anaconda3/lib/python3.8/site-packages/wtforms/form.py", line 208, in __call__
    return type.__call__(cls, *args, **kwargs)
TypeError: __init__() missing 1 required positional argument: 'original_username'
2021-02-03 23:06:18,816 ERROR: Exception on /edit_profile [GET] [in /Users/shihab/opt/anaconda3/lib/python3.8/site-packages/flask/app.py:1891]
Traceback (most recent call last):
  File "/Users/shihab/opt/anaconda3/lib/python3.8/site-packages/flask/app.py", line 2447, in wsgi_app
    response = self.full_dispatch_request()
  File "/Users/shihab/opt/anaconda3/lib/python3.8/site-packages/flask/app.py", line 1952, in full_dispatch_request
    rv = self.handle_user_exception(e)
  File "/Users/shihab/opt/anaconda3/lib/python3.8/site-packages/flask/app.py", line 1821, in handle_user_exception
    reraise(exc_type, exc_value, tb)
  File "/Users/shihab/opt/anaconda3/lib/python3.8/site-packages/flask/_compat.py", line 39, in reraise
    raise value
  File "/Users/shihab/opt/anaconda3/lib/python3.8/site-packages/flask/app.py", line 1950, in full_dispatch_request
    rv = self.dispatch_request()
  File "/Users/shihab/opt/anaconda3/lib/python3.8/site-packages/flask/app.py", line 1936, in dispatch_request
    return self.view_functions[rule.endpoint](**req.view_args)
  File "/Users/shihab/opt/anaconda3/lib/python3.8/site-packages/flask_login/utils.py", line 272, in decorated_view
    return func(*args, **kwargs)
  File "/Volumes/Space/Programming/microBlogFlask/myapp/routes.py", line 97, in edit_profile
    form = EditProfileForm()
  File "/Users/shihab/opt/anaconda3/lib/python3.8/site-packages/wtforms/form.py", line 208, in __call__
    return type.__call__(cls, *args, **kwargs)
TypeError: __init__() missing 1 required positional argument: 'original_username'
2021-02-03 23:06:41,792 ERROR: Exception on /edit_profile [GET] [in /Users/shihab/opt/anaconda3/lib/python3.8/site-packages/flask/app.py:1891]
Traceback (most recent call last):
  File "/Users/shihab/opt/anaconda3/lib/python3.8/site-packages/flask/app.py", line 2447, in wsgi_app
    response = self.full_dispatch_request()
  File "/Users/shihab/opt/anaconda3/lib/python3.8/site-packages/flask/app.py", line 1952, in full_dispatch_request
    rv = self.handle_user_exception(e)
  File "/Users/shihab/opt/anaconda3/lib/python3.8/site-packages/flask/app.py", line 1821, in handle_user_exception
    reraise(exc_type, exc_value, tb)
  File "/Users/shihab/opt/anaconda3/lib/python3.8/site-packages/flask/_compat.py", line 39, in reraise
    raise value
  File "/Users/shihab/opt/anaconda3/lib/python3.8/site-packages/flask/app.py", line 1950, in full_dispatch_request
    rv = self.dispatch_request()
  File "/Users/shihab/opt/anaconda3/lib/python3.8/site-packages/flask/app.py", line 1936, in dispatch_request
    return self.view_functions[rule.endpoint](**req.view_args)
  File "/Users/shihab/opt/anaconda3/lib/python3.8/site-packages/flask_login/utils.py", line 272, in decorated_view
    return func(*args, **kwargs)
  File "/Volumes/Space/Programming/microBlogFlask/myapp/routes.py", line 97, in edit_profile
    form = EditProfileForm()
  File "/Users/shihab/opt/anaconda3/lib/python3.8/site-packages/wtforms/form.py", line 208, in __call__
    return type.__call__(cls, *args, **kwargs)
TypeError: __init__() missing 1 required positional argument: 'original_username'
2021-02-03 23:06:49,226 ERROR: Exception on /edit_profile [GET] [in /Users/shihab/opt/anaconda3/lib/python3.8/site-packages/flask/app.py:1891]
Traceback (most recent call last):
  File "/Users/shihab/opt/anaconda3/lib/python3.8/site-packages/flask/app.py", line 2447, in wsgi_app
    response = self.full_dispatch_request()
  File "/Users/shihab/opt/anaconda3/lib/python3.8/site-packages/flask/app.py", line 1952, in full_dispatch_request
    rv = self.handle_user_exception(e)
  File "/Users/shihab/opt/anaconda3/lib/python3.8/site-packages/flask/app.py", line 1821, in handle_user_exception
    reraise(exc_type, exc_value, tb)
  File "/Users/shihab/opt/anaconda3/lib/python3.8/site-packages/flask/_compat.py", line 39, in reraise
    raise value
  File "/Users/shihab/opt/anaconda3/lib/python3.8/site-packages/flask/app.py", line 1950, in full_dispatch_request
    rv = self.dispatch_request()
  File "/Users/shihab/opt/anaconda3/lib/python3.8/site-packages/flask/app.py", line 1936, in dispatch_request
    return self.view_functions[rule.endpoint](**req.view_args)
  File "/Users/shihab/opt/anaconda3/lib/python3.8/site-packages/flask_login/utils.py", line 272, in decorated_view
    return func(*args, **kwargs)
  File "/Volumes/Space/Programming/microBlogFlask/myapp/routes.py", line 97, in edit_profile
    form = EditProfileForm()
  File "/Users/shihab/opt/anaconda3/lib/python3.8/site-packages/wtforms/form.py", line 208, in __call__
    return type.__call__(cls, *args, **kwargs)
TypeError: __init__() missing 1 required positional argument: 'original_username'
2021-02-06 16:28:33,393 INFO: microBlog startup [in /Volumes/Space/Programming/microBlogFlask/myapp/__init__.py:47]
2021-02-06 16:29:29,376 INFO: microBlog startup [in /Volumes/Space/Programming/microBlogFlask/myapp/__init__.py:47]
2021-02-06 16:34:43,069 INFO: microBlog startup [in /Volumes/Space/Programming/microBlogFlask/myapp/__init__.py:47]
2021-02-06 16:35:48,266 INFO: microBlog startup [in /Volumes/Space/Programming/microBlogFlask/myapp/__init__.py:47]
2021-02-06 16:36:12,005 INFO: microBlog startup [in /Volumes/Space/Programming/microBlogFlask/myapp/__init__.py:47]
2021-02-06 16:42:43,506 INFO: microBlog startup [in /Volumes/Space/Programming/microBlogFlask/myapp/__init__.py:47]
2021-02-06 16:43:16,050 INFO: microBlog startup [in /Volumes/Space/Programming/microBlogFlask/myapp/__init__.py:47]
2021-02-06 16:43:33,774 INFO: microBlog startup [in /Volumes/Space/Programming/microBlogFlask/myapp/__init__.py:47]
2021-02-06 16:44:04,964 INFO: microBlog startup [in /Volumes/Space/Programming/microBlogFlask/myapp/__init__.py:47]
2021-02-06 16:45:26,590 INFO: microBlog startup [in /Volumes/Space/Programming/microBlogFlask/myapp/__init__.py:47]
2021-02-06 16:52:31,802 INFO: microBlog startup [in /Volumes/Space/Programming/microBlogFlask/myapp/__init__.py:47]
